Workbook

Sheet Filtro por plano
A1: Filtro por plano: os 6 grupos do k-means para o plano escolhido
A2: Escolha o plano na célula amarela. Os grupos são os mesmos do modelo global (o plano não é variável do k-means).
A4: Plano selecionado: | B4: Todos
A6: Grupo | B6: Clientes | C6: % de clientes | D6: Valor pago acumulado (R$) | E6: % da receita | F6: Receita média (R$) | G6: Cancelamento em 90 dias | H6: Cupons por cliente | I6: Oferta recomendada
A7: Cinéfilos de cupom | B7: =SUMPRODUCT(('Dados por plano'!$B$5:$B$22=$A7)*((($B$4="Todos")+('Dados por plano'!$A$5:$A$22=$B$4))>0)*'Dados por plano'!$C$5:$C$22) -> 165871 | C7: =B7/SUM($B$7:$B$12) -> 0.24734826 | D7: =SUMPRODUCT(('Dados por plano'!$B$5:$B$22=$A7)*((($B$4="Todos")+('Dados por plano'!$A$5:$A$22=$B$4))>0)*'Dados por plano'!$D$5:$D$22) -> 1.6514883e+08 | E7: =D7/SUM($D$7:$D$12) -> 0.38461593 | F7: =IFERROR(D7/B7,0) -> 995.64617 | G7: =IFERROR(SUMPRODUCT(('Dados por plano'!$B$5:$B$22=$A7)*((($B$4="Todos")+('Dados por plano'!$A$5:$A$22=$B$4))>0)*'Dados por plano'!$E$5:$E$22)/B7,0) -> 0.12075649 | H7: =IFERROR(SUMPRODUCT(('Dados por plano'!$B$5:$B$22=$A7)*((($B$4="Todos")+('Dados por plano'!$A$5:$A$22=$B$4))>0)*'Dados por plano'!$F$5:$F$22)/B7,0) -> 1.3395918 | I7: =INDEX('Grupos e ações'!$L$5:$L$10,MATCH(A7,'Grupos e ações'!$A$5:$A$10,0)) -> Pacote de 3 aluguéis com 30% off (desconto no filme, não na assinatura); convite para anual/Família.
A8: Fiéis a preço cheio | B8: =SUMPRODUCT(('Dados por plano'!$B$5:$B$22=$A8)*((($B$4="Todos")+('Dados por plano'!$A$5:$A$22=$B$4))>0)*'Dados por plano'!$C$5:$C$22) -> 142050 | C8: =B8/SUM($B$7:$B$12) -> 0.21182618 | D8: =SUMPRODUCT(('Dados por plano'!$B$5:$B$22=$A8)*((($B$4="Todos")+('Dados por plano'!$A$5:$A$22=$B$4))>0)*'Dados por plano'!$D$5:$D$22) -> 1.3744519e+08 | E8: =D8/SUM($D$7:$D$12) -> 0.3200968 | F8: =IFERROR(D8/B8,0) -> 967.5832 | G8: =IFERROR(SUMPRODUCT(('Dados por plano'!$B$5:$B$22=$A8)*((($B$4="Todos")+('Dados por plano'!$A$5:$A$22=$B$4))>0)*'Dados por plano'!$E$5:$E$22)/B8,0) -> 0.10215417 | H8: =IFERROR(SUMPRODUCT(('Dados por plano'!$B$5:$B$22=$A8)*((($B$4="Todos")+('Dados por plano'!$A$5:$A$22=$B$4))>0)*'Dados por plano'!$F$5:$F$22)/B8,0) -> 0.00024903203 | I8: =INDEX('Grupos e ações'!$L$5:$L$10,MATCH(A8,'Grupos e ações'!$A$5:$A$10,0)) -> Sem desconto. Preço travado no plano anual ou benefício não monetário (estreia antecipada).
A9: Esfriando (alto valor) | B9: =SUMPRODUCT(('Dados por plano'!$B$5:$B$22=$A9)*((($B$4="Todos")+('Dados por plano'!$A$5:$A$22=$B$4))>0)*'Dados por plano'!$C$5:$C$22) -> 109123 | C9: =B9/SUM($B$7:$B$12) -> 0.16272515 | D9: =SUMPRODUCT(('Dados por plano'!$B$5:$B$22=$A9)*((($B$4="Todos")+('Dados por plano'!$A$5:$A$22=$B$4))>0)*'Dados por plano'!$D$5:$D$22) -> 73330429 | E9: =D9/SUM($D$7:$D$12) -> 0.1707796 | F9: =IFERROR(D9/B9,0) -> 671.99792 | G9: =IFERROR(SUMPRODUCT(('Dados por plano'!$B$5:$B$22=$A9)*((($B$4="Todos")+('Dados por plano'!$A$5:$A$22=$B$4))>0)*'Dados por plano'!$E$5:$E$22)/B9,0) -> 0.27406688 | H9: =IFERROR(SUMPRODUCT(('Dados por plano'!$B$5:$B$22=$A9)*((($B$4="Todos")+('Dados por plano'!$A$5:$A$22=$B$4))>0)*'Dados por plano'!$F$5:$F$22)/B9,0) -> 0.25236406 | I9: =INDEX('Grupos e ações'!$L$5:$L$10,MATCH(A9,'Grupos e ações'!$A$5:$A$10,0)) -> Crédito de aluguel de R$ 15 ou 1 canal extra por 1 mês (custo menor que desconto na mensalidade); contato ativo para Família.
A10: Novatos em experimentação | B10: =SUMPRODUCT(('Dados por plano'!$B$5:$B$22=$A10)*((($B$4="Todos")+('Dados por plano'!$A$5:$A$22=$B$4))>0)*'Dados por plano'!$C$5:$C$22) -> 131207 | C10: =B10/SUM($B$7:$B$12) -> 0.195657 | D10: =SUMPRODUCT(('Dados por plano'!$B$5:$B$22=$A10)*((($B$4="Todos")+('Dados por plano'!$A$5:$A$22=$B$4))>0)*'Dados por plano'!$D$5:$D$22) -> 23554800 | E10: =D10/SUM($D$7:$D$12) -> 0.054856891 | F10: =IFERROR(D10/B10,0) -> 179.52396 | G10: =IFERROR(SUMPRODUCT(('Dados por plano'!$B$5:$B$22=$A10)*((($B$4="Todos")+('Dados por plano'!$A$5:$A$22=$B$4))>0)*'Dados por plano'!$E$5:$E$22)/B10,0) -> 0.19540878 | H10: =IFERROR(SUMPRODUCT(('Dados por plano'!$B$5:$B$22=$A10)*((($B$4="Todos")+('Dados por plano'!$A$5:$A$22=$B$4))>0)*'Dados por plano'!$F$5:$F$22)/B10,0) -> 0.30304563 | I10: =INDEX('Grupos e ações'!$L$5:$L$10,MATCH(A10,'Grupos e ações'!$A$5:$A$10,0)) -> 1º aluguel grátis; aviso do fim da promo no 45º dia com migração para anual.
A11: Presenteados | B11: =SUMPRODUCT(('Dados por plano'!$B$5:$B$22=$A11)*((($B$4="Todos")+('Dados por plano'!$A$5:$A$22=$B$4))>0)*'Dados por plano'!$C$5:$C$22) -> 35580 | C11: =B11/SUM($B$7:$B$12) -> 0.053057201 | D11: =SUMPRODUCT(('Dados por plano'!$B$5:$B$22=$A11)*((($B$4="Todos")+('Dados por plano'!$A$5:$A$22=$B$4))>0)*'Dados por plano'!$D$5:$D$22) -> 20661581 | E11: =D11/SUM($D$7:$D$12) -> 0.048118859 | F11: =IFERROR(D11/B11,0) -> 580.70772 | G11: =IFERROR(SUMPRODUCT(('Dados por plano'!$B$5:$B$22=$A11)*((($B$4="Todos")+('Dados por plano'!$A$5:$A$22=$B$4))>0)*'Dados por plano'!$E$5:$E$22)/B11,0) -> 0.29041596 | H11: =IFERROR(SUMPRODUCT(('Dados por plano'!$B$5:$B$22=$A11)*((($B$4="Todos")+('Dados por plano'!$A$5:$A$22=$B$4))>0)*'Dados por plano'!$F$5:$F$22)/B11,0) -> 0.46304469 | I11: =INDEX('Grupos e ações'!$L$5:$L$10,MATCH(A11,'Grupos e ações'!$A$5:$A$10,0)) -> 1º mês próprio com 40% off, sem fidelidade; opção de migrar a cobrança para a fatura Claro.
A12: Quase perdidos | B12: =SUMPRODUCT(('Dados por plano'!$B$5:$B$22=$A12)*((($B$4="Todos")+('Dados por plano'!$A$5:$A$22=$B$4))>0)*'Dados por plano'!$C$5:$C$22) -> 86766 | C12: =B12/SUM($B$7:$B$12) -> 0.1293862 | D12: =SUMPRODUCT(('Dados por plano'!$B$5:$B$22=$A12)*((($B$4="Todos")+('Dados por plano'!$A$5:$A$22=$B$4))>0)*'Dados por plano'!$D$5:$D$22) -> 9245512.5 | E12: =D12/SUM($D$7:$D$12) -> 0.02153192 | F12: =IFERROR(D12/B12,0) -> 106.55686 | G12: =IFERROR(SUMPRODUCT(('Dados por plano'!$B$5:$B$22=$A12)*((($B$4="Todos")+('Dados por plano'!$A$5:$A$22=$B$4))>0)*'Dados por plano'!$E$5:$E$22)/B12,0) -> 0.50814835 | H12: =IFERROR(SUMPRODUCT(('Dados por plano'!$B$5:$B$22=$A12)*((($B$4="Todos")+('Dados por plano'!$A$5:$A$22=$B$4))>0)*'Dados por plano'!$F$5:$F$22)/B12,0) -> 0.44679394 | I12: =INDEX('Grupos e ações'!$L$5:$L$10,MATCH(A12,'Grupos e ações'!$A$5:$A$10,0)) -> Sem desconto de entrada; oferecer pausa da assinatura ou downgrade de plano no fluxo de cancelamento.
A13: Total | B13: =SUM(B7:B12) -> 670597 | C13: =SUM(C7:C12) -> 1 | D13: =SUM(D7:D12) -> 4.2938634e+08 | E13: =SUM(E7:E12) -> 1 | F13: =D13/B13 -> 640.3046 | G13: =SUMPRODUCT(B7:B12,G7:G12)/B13 -> 0.21549455
A36: Comparativo: % de clientes de cada grupo por plano (base 26/07/2026)
A37: Grupo | B37: Todos | C37: Premiere Futebol | D37: Telecine | E37: Plano Família Claro tv+ | F37: Premiere vs Todos (p.p.) | G37: Telecine vs Todos (p.p.) | H37: Família vs Todos (p.p.)
A38: Cinéfilos de cupom | B38: =SUMIFS('Dados por plano'!$C$5:$C$22,'Dados por plano'!$B$5:$B$22,$A38)/SUM('Dados por plano'!$C$5:$C$22) -> 0.24734826 | C38: =SUMIFS('Dados por plano'!$C$5:$C$22,'Dados por plano'!$B$5:$B$22,$A38,'Dados por plano'!$A$5:$A$22,"Premiere Futebol")/SUMIFS('Dados por plano'!$C$5:$C$22,'Dados por plano'!$A$5:$A$22,"Premiere Futebol") -> 0.24298041 | D38: =SUMIFS('Dados por plano'!$C$5:$C$22,'Dados por plano'!$B$5:$B$22,$A38,'Dados por plano'!$A$5:$A$22,"Telecine")/SUMIFS('Dados por plano'!$C$5:$C$22,'Dados por plano'!$A$5:$A$22,"Telecine") -> 0.21000429 | E38: =SUMIFS('Dados por plano'!$C$5:$C$22,'Dados por plano'!$B$5:$B$22,$A38,'Dados por plano'!$A$5:$A$22,"Plano Família Claro tv+")/SUMIFS('Dados por plano'!$C$5:$C$22,'Dados por plano'!$A$5:$A$22,"Plano Família Claro tv+") -> 0.26966718 | F38: =(C38-$B38)*100 -> -0.43678434 | G38: =(D38-$B38)*100 -> -3.7343971 | H38: =(E38-$B38)*100 -> 2.2318926
A39: Fiéis a preço cheio | B39: =SUMIFS('Dados por plano'!$C$5:$C$22,'Dados por plano'!$B$5:$B$22,$A39)/SUM('Dados por plano'!$C$5:$C$22) -> 0.21182618 | C39: =SUMIFS('Dados por plano'!$C$5:$C$22,'Dados por plano'!$B$5:$B$22,$A39,'Dados por plano'!$A$5:$A$22,"Premiere Futebol")/SUMIFS('Dados por plano'!$C$5:$C$22,'Dados por plano'!$A$5:$A$22,"Premiere Futebol") -> 0.19383847 | D39: =SUMIFS('Dados por plano'!$C$5:$C$22,'Dados por plano'!$B$5:$B$22,$A39,'Dados por plano'!$A$5:$A$22,"Telecine")/SUMIFS('Dados por plano'!$C$5:$C$22,'Dados por plano'!$A$5:$A$22,"Telecine") -> 0.15642655 | E39: =SUMIFS('Dados por plano'!$C$5:$C$22,'Dados por plano'!$B$5:$B$22,$A39,'Dados por plano'!$A$5:$A$22,"Plano Família Claro tv+")/SUMIFS('Dados por plano'!$C$5:$C$22,'Dados por plano'!$A$5:$A$22,"Plano Família Claro tv+") -> 0.25270096 | F39: =(C39-$B39)*100 -> -1.7987707 | G39: =(D39-$B39)*100 -> -5.5399625 | H39: =(E39-$B39)*100 -> 4.0874778
A40: Esfriando (alto valor) | B40: =SUMIFS('Dados por plano'!$C$5:$C$22,'Dados por plano'!$B$5:$B$22,$A40)/SUM('Dados por plano'!$C$5:$C$22) -> 0.16272515 | C40: =SUMIFS('Dados por plano'!$C$5:$C$22,'Dados por plano'!$B$5:$B$22,$A40,'Dados por plano'!$A$5:$A$22,"Premiere Futebol")/SUMIFS('Dados por plano'!$C$5:$C$22,'Dados por plano'!$A$5:$A$22,"Premiere Futebol") -> 0.18112275 | D40: =SUMIFS('Dados por plano'!$C$5:$C$22,'Dados por plano'!$B$5:$B$22,$A40,'Dados por plano'!$A$5:$A$22,"Telecine")/SUMIFS('Dados por plano'!$C$5:$C$22,'Dados por plano'!$A$5:$A$22,"Telecine") -> 0.17816157 | E40: =SUMIFS('Dados por plano'!$C$5:$C$22,'Dados por plano'!$B$5:$B$22,$A40,'Dados por plano'!$A$5:$A$22,"Plano Família Claro tv+")/SUMIFS('Dados por plano'!$C$5:$C$22,'Dados por plano'!$A$5:$A$22,"Plano Família Claro tv+") -> 0.14230436 | F40: =(C40-$B40)*100 -> 1.8397592 | G40: =(D40-$B40)*100 -> 1.5436418 | H40: =(E40-$B40)*100 -> -2.0420795
A41: Novatos em experimentação | B41: =SUMIFS('Dados por plano'!$C$5:$C$22,'Dados por plano'!$B$5:$B$22,$A41)/SUM('Dados por plano'!$C$5:$C$22) -> 0.195657 | C41: =SUMIFS('Dados por plano'!$C$5:$C$22,'Dados por plano'!$B$5:$B$22,$A41,'Dados por plano'!$A$5:$A$22,"Premiere Futebol")/SUMIFS('Dados por plano'!$C$5:$C$22,'Dados por plano'!$A$5:$A$22,"Premiere Futebol") -> 0.19328583 | D41: =SUMIFS('Dados por plano'!$C$5:$C$22,'Dados por plano'!$B$5:$B$22,$A41,'Dados por plano'!$A$5:$A$22,"Telecine")/SUMIFS('Dados por plano'!$C$5:$C$22,'Dados por plano'!$A$5:$A$22,"Telecine") -> 0.21904005 | E41: =SUMIFS('Dados por plano'!$C$5:$C$22,'Dados por plano'!$B$5:$B$22,$A41,'Dados por plano'!$A$5:$A$22,"Plano Família Claro tv+")/SUMIFS('Dados por plano'!$C$5:$C$22,'Dados por plano'!$A$5:$A$22,"Plano Família Claro tv+") -> 0.18512716 | F41: =(C41-$B41)*100 -> -0.2371179 | G41: =(D41-$B41)*100 -> 2.3383048 | H41: =(E41-$B41)*100 -> -1.0529847
A42: Presenteados | B42: =SUMIFS('Dados por plano'!$C$5:$C$22,'Dados por plano'!$B$5:$B$22,$A42)/SUM('Dados por plano'!$C$5:$C$22) -> 0.053057201 | C42: =SUMIFS('Dados por plano'!$C$5:$C$22,'Dados por plano'!$B$5:$B$22,$A42,'Dados por plano'!$A$5:$A$22,"Premiere Futebol")/SUMIFS('Dados por plano'!$C$5:$C$22,'Dados por plano'!$A$5:$A$22,"Premiere Futebol") -> 0.051032577 | D42: =SUMIFS('Dados por plano'!$C$5:$C$22,'Dados por plano'!$B$5:$B$22,$A42,'Dados por plano'!$A$5:$A$22,"Telecine")/SUMIFS('Dados por plano'!$C$5:$C$22,'Dados por plano'!$A$5:$A$22,"Telecine") -> 0.053186794 | E42: =SUMIFS('Dados por plano'!$C$5:$C$22,'Dados por plano'!$B$5:$B$22,$A42,'Dados por plano'!$A$5:$A$22,"Plano Família Claro tv+")/SUMIFS('Dados por plano'!$C$5:$C$22,'Dados por plano'!$A$5:$A$22,"Plano Família Claro tv+") -> 0.054356039 | F42: =(C42-$B42)*100 -> -0.20246242 | G42: =(D42-$B42)*100 -> 0.012959252 | H42: =(E42-$B42)*100 -> 0.12988377
A43: Quase perdidos | B43: =SUMIFS('Dados por plano'!$C$5:$C$22,'Dados por plano'!$B$5:$B$22,$A43)/SUM('Dados por plano'!$C$5:$C$22) -> 0.1293862 | C43: =SUMIFS('Dados por plano'!$C$5:$C$22,'Dados por plano'!$B$5:$B$22,$A43,'Dados por plano'!$A$5:$A$22,"Premiere Futebol")/SUMIFS('Dados por plano'!$C$5:$C$22,'Dados por plano'!$A$5:$A$22,"Premiere Futebol") -> 0.13773997 | D43: =SUMIFS('Dados por plano'!$C$5:$C$22,'Dados por plano'!$B$5:$B$22,$A43,'Dados por plano'!$A$5:$A$22,"Telecine")/SUMIFS('Dados por plano'!$C$5:$C$22,'Dados por plano'!$A$5:$A$22,"Telecine") -> 0.18318074 | E43: =SUMIFS('Dados por plano'!$C$5:$C$22,'Dados por plano'!$B$5:$B$22,$A43,'Dados por plano'!$A$5:$A$22,"Plano Família Claro tv+")/SUMIFS('Dados por plano'!$C$5:$C$22,'Dados por plano'!$A$5:$A$22,"Plano Família Claro tv+") -> 0.095844305 | F43: =(C43-$B43)*100 -> 0.83537615 | G43: =(D43-$B43)*100 -> 5.3794537 | H43: =(E43-$B43)*100 -> -3.3541899
A45: Comparativo: % da receita de cada grupo por plano
A46: Grupo | B46: Todos | C46: Premiere Futebol | D46: Telecine | E46: Plano Família Claro tv+
A47: Cinéfilos de cupom | B47: =SUMIFS('Dados por plano'!$D$5:$D$22,'Dados por plano'!$B$5:$B$22,$A47)/SUM('Dados por plano'!$D$5:$D$22) -> 0.38461593 | C47: =SUMIFS('Dados por plano'!$D$5:$D$22,'Dados por plano'!$B$5:$B$22,$A47,'Dados por plano'!$A$5:$A$22,"Premiere Futebol")/SUMIFS('Dados por plano'!$D$5:$D$22,'Dados por plano'!$A$5:$A$22,"Premiere Futebol") -> 0.37269345 | D47: =SUMIFS('Dados por plano'!$D$5:$D$22,'Dados por plano'!$B$5:$B$22,$A47,'Dados por plano'!$A$5:$A$22,"Telecine")/SUMIFS('Dados por plano'!$D$5:$D$22,'Dados por plano'!$A$5:$A$22,"Telecine") -> 0.35080745 | E47: =SUMIFS('Dados por plano'!$D$5:$D$22,'Dados por plano'!$B$5:$B$22,$A47,'Dados por plano'!$A$5:$A$22,"Plano Família Claro tv+")/SUMIFS('Dados por plano'!$D$5:$D$22,'Dados por plano'!$A$5:$A$22,"Plano Família Claro tv+") -> 0.39646087
A48: Fiéis a preço cheio | B48: =SUMIFS('Dados por plano'!$D$5:$D$22,'Dados por plano'!$B$5:$B$22,$A48)/SUM('Dados por plano'!$D$5:$D$22) -> 0.3200968 | C48: =SUMIFS('Dados por plano'!$D$5:$D$22,'Dados por plano'!$B$5:$B$22,$A48,'Dados por plano'!$A$5:$A$22,"Premiere Futebol")/SUMIFS('Dados por plano'!$D$5:$D$22,'Dados por plano'!$A$5:$A$22,"Premiere Futebol") -> 0.28734561 | D48: =SUMIFS('Dados por plano'!$D$5:$D$22,'Dados por plano'!$B$5:$B$22,$A48,'Dados por plano'!$A$5:$A$22,"Telecine")/SUMIFS('Dados por plano'!$D$5:$D$22,'Dados por plano'!$A$5:$A$22,"Telecine") -> 0.25158735 | E48: =SUMIFS('Dados por plano'!$D$5:$D$22,'Dados por plano'!$B$5:$B$22,$A48,'Dados por plano'!$A$5:$A$22,"Plano Família Claro tv+")/SUMIFS('Dados por plano'!$D$5:$D$22,'Dados por plano'!$A$5:$A$22,"Plano Família Claro tv+") -> 0.34764748
A49: Esfriando (alto valor) | B49: =SUMIFS('Dados por plano'!$D$5:$D$22,'Dados por plano'!$B$5:$B$22,$A49)/SUM('Dados por plano'!$D$5:$D$22) -> 0.1707796 | C49: =SUMIFS('Dados por plano'!$D$5:$D$22,'Dados por plano'!$B$5:$B$22,$A49,'Dados por plano'!$A$5:$A$22,"Premiere Futebol")/SUMIFS('Dados por plano'!$D$5:$D$22,'Dados por plano'!$A$5:$A$22,"Premiere Futebol") -> 0.20722122 | D49: =SUMIFS('Dados por plano'!$D$5:$D$22,'Dados por plano'!$B$5:$B$22,$A49,'Dados por plano'!$A$5:$A$22,"Telecine")/SUMIFS('Dados por plano'!$D$5:$D$22,'Dados por plano'!$A$5:$A$22,"Telecine") -> 0.22515406 | E49: =SUMIFS('Dados por plano'!$D$5:$D$22,'Dados por plano'!$B$5:$B$22,$A49,'Dados por plano'!$A$5:$A$22,"Plano Família Claro tv+")/SUMIFS('Dados por plano'!$D$5:$D$22,'Dados por plano'!$A$5:$A$22,"Plano Família Claro tv+") -> 0.14459855
A50: Novatos em experimentação | B50: =SUMIFS('Dados por plano'!$D$5:$D$22,'Dados por plano'!$B$5:$B$22,$A50)/SUM('Dados por plano'!$D$5:$D$22) -> 0.054856891 | C50: =SUMIFS('Dados por plano'!$D$5:$D$22,'Dados por plano'!$B$5:$B$22,$A50,'Dados por plano'!$A$5:$A$22,"Premiere Futebol")/SUMIFS('Dados por plano'!$D$5:$D$22,'Dados por plano'!$A$5:$A$22,"Premiere Futebol") -> 0.060041875 | D50: =SUMIFS('Dados por plano'!$D$5:$D$22,'Dados por plano'!$B$5:$B$22,$A50,'Dados por plano'!$A$5:$A$22,"Telecine")/SUMIFS('Dados por plano'!$D$5:$D$22,'Dados por plano'!$A$5:$A$22,"Telecine") -> 0.083002625 | E50: =SUMIFS('Dados por plano'!$D$5:$D$22,'Dados por plano'!$B$5:$B$22,$A50,'Dados por plano'!$A$5:$A$22,"Plano Família Claro tv+")/SUMIFS('Dados por plano'!$D$5:$D$22,'Dados por plano'!$A$5:$A$22,"Plano Família Claro tv+") -> 0.046953654
A51: Presenteados | B51: =SUMIFS('Dados por plano'!$D$5:$D$22,'Dados por plano'!$B$5:$B$22,$A51)/SUM('Dados por plano'!$D$5:$D$22) -> 0.048118859 | C51: =SUMIFS('Dados por plano'!$D$5:$D$22,'Dados por plano'!$B$5:$B$22,$A51,'Dados por plano'!$A$5:$A$22,"Premiere Futebol")/SUMIFS('Dados por plano'!$D$5:$D$22,'Dados por plano'!$A$5:$A$22,"Premiere Futebol") -> 0.046414633 | D51: =SUMIFS('Dados por plano'!$D$5:$D$22,'Dados por plano'!$B$5:$B$22,$A51,'Dados por plano'!$A$5:$A$22,"Telecine")/SUMIFS('Dados por plano'!$D$5:$D$22,'Dados por plano'!$A$5:$A$22,"Telecine") -> 0.047651843 | E51: =SUMIFS('Dados por plano'!$D$5:$D$22,'Dados por plano'!$B$5:$B$22,$A51,'Dados por plano'!$A$5:$A$22,"Plano Família Claro tv+")/SUMIFS('Dados por plano'!$D$5:$D$22,'Dados por plano'!$A$5:$A$22,"Plano Família Claro tv+") -> 0.048918274
A52: Quase perdidos | B52: =SUMIFS('Dados por plano'!$D$5:$D$22,'Dados por plano'!$B$5:$B$22,$A52)/SUM('Dados por plano'!$D$5:$D$22) -> 0.02153192 | C52: =SUMIFS('Dados por plano'!$D$5:$D$22,'Dados por plano'!$B$5:$B$22,$A52,'Dados por plano'!$A$5:$A$22,"Premiere Futebol")/SUMIFS('Dados por plano'!$D$5:$D$22,'Dados por plano'!$A$5:$A$22,"Premiere Futebol") -> 0.026283214 | D52: =SUMIFS('Dados por plano'!$D$5:$D$22,'Dados por plano'!$B$5:$B$22,$A52,'Dados por plano'!$A$5:$A$22,"Telecine")/SUMIFS('Dados por plano'!$D$5:$D$22,'Dados por plano'!$A$5:$A$22,"Telecine") -> 0.041796669 | E52: =SUMIFS('Dados por plano'!$D$5:$D$22,'Dados por plano'!$B$5:$B$22,$A52,'Dados por plano'!$A$5:$A$22,"Plano Família Claro tv+")/SUMIFS('Dados por plano'!$D$5:$D$22,'Dados por plano'!$A$5:$A$22,"Plano Família Claro tv+") -> 0.015421171
A55: Base ativa hoje (24/10/2026): clientes por grupo no plano selecionado (para a ação de amanhã)
A56: Grupo | B56: Clientes ativos | C56: % do plano
A57: Cinéfilos de cupom | B57: =SUMPRODUCT(('Dados por plano'!$B$5:$B$22=$A57)*((($B$4="Todos")+('Dados por plano'!$A$5:$A$22=$B$4))>0)*'Dados por plano'!$G$5:$G$22) -> 187854 | C57: =B57/SUM($B$57:$B$62) -> 0.25582
A58: Fiéis a preço cheio | B58: =SUMPRODUCT(('Dados por plano'!$B$5:$B$22=$A58)*((($B$4="Todos")+('Dados por plano'!$A$5:$A$22=$B$4))>0)*'Dados por plano'!$G$5:$G$22) -> 173416 | C58: =B58/SUM($B$57:$B$62) -> 0.2361583
A59: Esfriando (alto valor) | B59: =SUMPRODUCT(('Dados por plano'!$B$5:$B$22=$A59)*((($B$4="Todos")+('Dados por plano'!$A$5:$A$22=$B$4))>0)*'Dados por plano'!$G$5:$G$22) -> 101466 | C59: =B59/SUM($B$57:$B$62) -> 0.13817663
A60: Novatos em experimentação | B60: =SUMPRODUCT(('Dados por plano'!$B$5:$B$22=$A60)*((($B$4="Todos")+('Dados por plano'!$A$5:$A$22=$B$4))>0)*'Dados por plano'!$G$5:$G$22) -> 148740 | C60: =B60/SUM($B$57:$B$62) -> 0.20255447
A61: Presenteados | B61: =SUMPRODUCT(('Dados por plano'!$B$5:$B$22=$A61)*((($B$4="Todos")+('Dados por plano'!$A$5:$A$22=$B$4))>0)*'Dados por plano'!$G$5:$G$22) -> 38558 | C61: =B61/SUM($B$57:$B$62) -> 0.052508372
A62: Quase perdidos | B62: =SUMPRODUCT(('Dados por plano'!$B$5:$B$22=$A62)*((($B$4="Todos")+('Dados por plano'!$A$5:$A$22=$B$4))>0)*'Dados por plano'!$G$5:$G$22) -> 84287 | C62: =B62/SUM($B$57:$B$62) -> 0.11478223
A64: Leitura: Família concentra mais "Fiéis a preço cheio" e "Cinéfilos de cupom"; Telecine concentra mais "Quase perdidos" e "Novatos". Parte disso é preço (o valor pago é menor no Telecine), não comportamento. Veja a aba "Cupons por plano".

Sheet Cupons por plano
A1: Cupons fazem sentido igualmente nos 3 planos? Não: a economia e o uso diferem
A2: Cupom de entrada = 40% off por 2 meses. Cupom de aluguel = desconto em compra/aluguel de filme. Base sintética.
A4: Indicador | B4: Premiere Futebol | C4: Telecine | D4: Plano Família Claro tv+ | E4: Leitura
A5: Preço de lista (R$/mês) | B5: 59.9 | C5: 37.9 | D5: 99.9
A6: Margem de contribuição (% do preço) | B6: 0.45 | C6: 0.58 | D6: 0.38 | E6: Premiere: direitos esportivos; Família repassa 4 OTTs.
A7: Margem nos 2 meses de promo (% do preço de lista) | B7: =0.6-(1-B6) -> 0.05 | C7: =0.6-(1-C6) -> 0.18 | D7: =0.6-(1-D6) -> -0.02 | E7: Família fica NEGATIVA com 40% off: cada mês de promo custa dinheiro.
A8: Custo do desconto por cliente (R$) | B8: =B5*0.4*2 -> 47.92 | C8: =C5*0.4*2 -> 30.32 | D8: =D5*0.4*2 -> 79.92
A9: Contribuição mensal a preço cheio (R$) | B9: =B5*B6 -> 26.955 | C9: =C5*C6 -> 21.982 | D9: =D5*D6 -> 37.962
A10: Meses de margem cheia para pagar o desconto | B10: =B8/B9 -> 1.7777778 | C10: =C8/C9 -> 1.3793103 | D10: =D8/D9 -> 2.1052632 | E10: Quanto maior, mais tempo o cliente precisa ficar para o cupom se pagar.
A11: Observado: retenção em 3 meses COM cupom de entrada | B11: 0.42294861 | C11: 0.37627236 | D11: 0.40867157
A12: Observado: retenção em 3 meses SEM cupom | B12: 0.58733578 | C12: 0.53294658 | D12: 0.56430832 | E12: Dentro de cada origem x aquisição, para comparar o igual com o igual.
A13: Observado: retenção em 12 meses COM cupom | B13: 0.21499408 | C13: 0.18263995 | D13: 0.21306555
A14: Observado: retenção em 12 meses SEM cupom | B14: 0.29612797 | C14: 0.25133878 | D14: 0.28525417
A15: Margem 12 meses COM cupom (R$/cliente, só assinatura) | B15: 115.96166 | C15: 85.69078 | D15: 161.00035
A16: Margem 12 meses SEM cupom (R$/cliente) | B16: 168.99065 | C16: 125.93537 | D16: 231.42734
A17: % de clientes com cupom que precisam ser INCREMENTAIS para o cupom se pagar | B17: =1-B15/B16 -> 0.31379836 | C17: =1-C15/C16 -> 0.31956543 | D17: =1-D15/D16 -> 0.30431577 | E17: Se menos que isso for incremental (não assinaria sem o cupom), o cupom destrói valor. Fórmula: 1 - margem com / margem sem.
A18: % das assinaturas com cupom de entrada | B18: 0.36521354 | C18: 0.31969792 | D18: 0.31416319 | E18: Praticamente iguais entre planos: é premissa da simulação, não resultado.
A19: Aluguéis por assinatura (24m) | B19: 0.94088194 | C19: 0.99518333 | D19: 1.0417269 | E19: Na vida real, assinante de futebol deve alugar menos que o de cinema.
A20: % dos aluguéis com cupom | B20: 0.17990287 | C20: 0.17929695 | D20: 0.1805329
A21: % da receita que vem de aluguel/compra (TVOD) | B21: 0.067932111 | C21: 0.11582538 | D21: 0.04625257
A24: Conclusões e política de cupom sugerida por plano
A25: Plano | B25: Faz sentido? | C25: Por quê | D25: Política sugerida | E25: Teste
A26: Premiere Futebol | B26: Só em janelas de calendário | C26: Valor ligado à temporada: cupom fora do início do campeonato atrai quem sai em dez/jan. Margem de 5% do preço na promo. | D26: Cupom no início do Brasileirão/Copa; preferir anual (12x R$ 29,90) a % de desconto; sem cupom de aluguel. | E26: A/B em jan/abr: cupom 20% x 40% x sem cupom; medir churn em dez/jan.
A27: Telecine | B27: Sim, o que mais faz sentido | C27: Preço baixo e margem alta (58%): desconto se paga em ~1,4 meses; aluguel de filme é complementar ao catálogo. | D27: Cupom de entrada de 30-40% por 1-2 meses e cupons de aluguel para ativar uso. | E27: A/B de cupom de aluguel x crédito fixo; medir uso e churn do 2º ciclo.
A28: Plano Família Claro tv+ | B28: Não como % de desconto | C28: Margem de 38%: com 40% off a margem nos 2 primeiros meses é negativa (-2% do preço) e o cupom leva 2,1 meses cheios para se pagar. | D28: Trocar % off por benefício de custo baixo (1 mês de OTT extra, upgrade temporário) e priorizar bundle com fibra/móvel. | E28: A/B: 40% off x benefício extra x sem cupom; medir margem em 12 meses.
A30: Limitação: na simulação o cupom de entrada tem o mesmo efeito de churn nos 3 planos e não aumenta o volume de aquisição (80 mil/mês fixos). Por isso a base mede o CUSTO e a perda de retenção do cupom, não o ganho de conversão; só um teste real mede a incrementalidade.

Sheet Grupos e ações
A1: Segmentação comportamental para o CRM (k-means, 6 grupos): base ativa em 26/07/2026 com churn observado até 24/10/2026
A2: Base sintética. Receita = valor pago acumulado até a data. Variáveis: R, F (pedidos), M, cupons, presente, NPS. Ordenado por % da receita.
A4: Grupo | B4: Clientes | C4: Receita acumulada (R$) | D4: % de clientes | E4: % da receita | F4: Receita média por cliente (R$) | G4: Cancelamento em 90 dias | H4: Canal mais comum (% do grupo) | I4: Canal com maior lift (x vs base) | J4: Perfil (mediana R dias | F pedidos | cupons | presente | NPS) | K4: Mensagem | L4: Oferta | M4: Canal / quando | N4: Gatilho e KPI
A5: Cinéfilos de cupom | B5: 165871 | C5: 1.6514883e+08 | D5: =B5/SUM($B$5:$B$10) -> 0.24734826 | E5: =C5/SUM($C$5:$C$10) -> 0.38461593 | F5: =C5/B5 -> 995.64617 | G5: 0.12075649 | H5: Cross-sell na venda de fibra/móvel (19%) | I5: Indicação (cliente Claro) (1.11x) | J5: R 1 | F 15.7 | cupons 1.34 | presente 0% | NPS 7.3 | K5: "A estreia que você esperava chegou: alugue com o seu cupom." | L5: Pacote de 3 aluguéis com 30% off (desconto no filme, não na assinatura); convite para anual/Família. | M5: Push no app + resumo na fatura Claro (fatura) ou e-mail (cartão) | N5: Gatilho: lançamento de catálogo. KPI: aluguéis/cliente, migração para anual.
A6: Fiéis a preço cheio | B6: 142050 | C6: 1.3744519e+08 | D6: =B6/SUM($B$5:$B$10) -> 0.21182618 | E6: =C6/SUM($C$5:$C$10) -> 0.3200968 | F6: =C6/B6 -> 967.5832 | G6: 0.10215417 | H6: Cross-sell na venda de fibra/móvel (20%) | I6: Indicação (cartão) (1.33x) | J6: R 1 | F 13.6 | cupons 0.00 | presente 0% | NPS 7.5 | K6: "Obrigado por ficar: acesso antecipado às estreias do seu plano." | L6: Sem desconto. Preço travado no plano anual ou benefício não monetário (estreia antecipada). | M6: E-mail + app; nunca cupom (evita treinar o cliente a esperar desconto) | N6: Gatilho: 6º ciclo. KPI: % anual, churn 90d.
A7: Esfriando (alto valor) | B7: 109123 | C7: 73330429 | D7: =B7/SUM($B$5:$B$10) -> 0.16272515 | E7: =C7/SUM($C$5:$C$10) -> 0.1707796 | F7: =C7/B7 -> 671.99792 | G7: 0.27406688 | H7: Cross-sell na venda de fibra/móvel (18%) | I7: Indicação (cartão) (1.15x) | J7: R 6 | F 9.5 | cupons 0.25 | presente 0% | NPS 5.4 | K7: "Faz uns dias que você não aparece: veja o que entrou no seu plano." | L7: Crédito de aluguel de R$ 15 ou 1 canal extra por 1 mês (custo menor que desconto na mensalidade); contato ativo para Família. | M7: WhatsApp/Minha Claro (fatura) ou e-mail+WhatsApp (cartão); ligação só para Família | N7: Gatilho: recência >=5 dias com queda de frequência. KPI: salvamento, margem líquida.
A8: Novatos em experimentação | B8: 131207 | C8: 23554800 | D8: =B8/SUM($B$5:$B$10) -> 0.195657 | E8: =C8/SUM($C$5:$C$10) -> 0.054856891 | F8: =C8/B8 -> 179.52396 | G8: 0.19540878 | H8: Cross-sell na venda de fibra/móvel (15%) | I8: App stores (orgânico) (1.19x) | J8: R 1 | F 3.0 | cupons 0.30 | presente 0% | NPS 7.5 | K8: "Seus 3 primeiros títulos para começar" + guia de ativação no seu aparelho. | L8: 1º aluguel grátis; aviso do fim da promo no 45º dia com migração para anual. | M8: Push + WhatsApp (fatura) ou e-mail (cartão) | N8: Gatilho: D0, D7, D45. KPI: ativação D7, churn ciclos 2-3.
A9: Presenteados | B9: 35580 | C9: 20661581 | D9: =B9/SUM($B$5:$B$10) -> 0.053057201 | E9: =C9/SUM($C$5:$C$10) -> 0.048118859 | F9: =C9/B9 -> 580.70772 | G9: 0.29041596 | H9: Cross-sell na venda de fibra/móvel (20%) | I9: Indicação (cliente Claro) (1.21x) | J9: R 2 | F 7.0 | cupons 0.46 | presente 100% | NPS 5.5 | K9: "Gostou? Continue com a sua própria assinatura" (e-mail do 3º mês, ver Tarefa 2). | L9: 1º mês próprio com 40% off, sem fidelidade; opção de migrar a cobrança para a fatura Claro. | M9: E-mail + SMS no 3º mês (e lembrete em D80) | N9: Gatilho: 3º mês do presente. KPI: conversão para assinatura própria.
A10: Quase perdidos | B10: 86766 | C10: 9245512.5 | D10: =B10/SUM($B$5:$B$10) -> 0.1293862 | E10: =C10/SUM($C$5:$C$10) -> 0.02153192 | F10: =C10/B10 -> 106.55686 | G10: 0.50814835 | H10: Google Ads (15%) | I10: Afiliados/CPA (1.73x) | J10: R 5 | F 2.0 | cupons 0.45 | presente 0% | NPS 5.0 | K10: "Sentimos sua falta" (mensagem curta, uma única vez). | L10: Sem desconto de entrada; oferecer pausa da assinatura ou downgrade de plano no fluxo de cancelamento. | M10: E-mail/SMS automatizado (custo baixo); revisar públicos de mídia paga que originam este grupo | N10: Gatilho: recência >30 dias. KPI: reativação, custo por reativado.
A11: Total | B11: =SUM(B5:B10) -> 670597 | C11: =SUM(C5:C10) -> 4.2938634e+08 | D11: =SUM(D5:D10) -> 1 | E11: =SUM(E5:E10) -> 1
A12: Canal mais comum reflete o tamanho do canal (cross-sell é o maior); use a coluna de lift para ver onde o grupo está sobre-representado.

Sheet Exploração
A1: Exploração da base (1,92 mi assinaturas, 24 meses)
A4: Pedidos por assinatura (ciclos + aluguéis + compras)
A5: Estatística | B5: Valor
A6: count | B6: 1920000
A7: mean | B7: 7.05
A8: std | B8: 7.26
A9: min | B9: 1
A10: 10% | B10: 1
A11: 25% | B11: 2
A12: 50% | B12: 4
A13: 75% | B13: 10
A14: 90% | B14: 19
A15: 99% | B15: 29
A16: max | B16: 44
A18: Receita acumulada por assinatura (R$)
A19: Estatística | B19: Valor
A20: count | B20: 1920000
A21: mean | B21: 439.16
A22: std | B22: 508.97
A23: min | B23: 22.74
A24: 10% | B24: 45.48
A25: 25% | B25: 95.97
A26: 50% | B26: 219.78
A27: 75% | B27: 612.21
A28: 90% | B28: 1168.68
A29: 99% | B29: 2287.07
A30: max | B30: 2935.09
A32: Recência (dias sem acesso)
A33: Estatística | B33: Valor
A34: count | B34: 1920000
A35: mean | B35: 5.7
A36: std | B36: 10.03
A37: min | B37: 0
A38: 10% | B38: 0
A39: 25% | B39: 1
A40: 50% | B40: 3
A41: 75% | B41: 6
A42: 90% | B42: 14
A43: 99% | B43: 52
A44: max | B44: 90
...

Sheet Escolha de k
A1: Teste de k = 3 a 7 (k-means, 6 variáveis padronizadas, amostra de 150 mil, n_init=10)
A4: k | B4: Inércia | C4: Silhouette (maior = melhor) | D4: Calinski-Harabasz (maior) | E4: Davies-Bouldin (menor) | F4: Menor grupo (% base) | G4: ARI médio entre 5 sementes/amostras | H4: ARI mínimo | I4: ARI k vs k+1
A5: 3 | B5: 537352.25 | C5: 0.27919912 | D5: 50543.466 | E5: 1.2506482 | F5: 0.0527 | G5: 0.76609137 | H5: 0.42779263 | I5: 0.51113092
A6: 4 | B6: 450122.28 | C6: 0.25410601 | D6: 49915.811 | E6: 1.3039281 | F6: 0.0527 | G6: 0.99479492 | H6: 0.99197589 | I6: 0.73391964
A7: 5 | B7: 401839.44 | C7: 0.24069111 | D7: 46441.717 | E7: 1.3900995 | F7: 0.0527 | G7: 0.95067766 | H7: 0.90215435 | I7: 0.6896117
A8: 6 | B8: 367847.56 | C8: 0.22219463 | D8: 43357.156 | E8: 1.356749 | F8: 0.0527 | G8: 0.94738335 | H8: 0.89794457 | I8: 0.76092426
A9: 7 | B9: 341657.44 | C9: 0.21562871 | D9: 40816.448 | E9: 1.3014585 | F9: 0.0527 | G9: 0.86704054 | H9: 0.71467182
A12: Escolha: k = 6.
A13: • Silhouette cai com k (0,28 em k=3 para 0,22 em k=6): a estrutura é fraca/contínua, não há "ilhas" naturais; k serve para ação, não para descoberta.
A14: • k=3 é instável (ARI mínimo 0,43). k=4 é o mais estável (0,99), mas junta "esfriando" com "novatos". k=5 e k=6 têm estabilidade equivalente (ARI ~0,95).
A15: • k=6 tem Davies-Bouldin melhor que k=5 e separa dois públicos com ações diferentes: "Esfriando (alto valor)" (27% de cancelamento, 17% da receita) e "Quase perdidos" (51%, 2%).
A16: • k=7 perde estabilidade (ARI mínimo 0,72) e cria grupos pequenos demais para o CRM operar amanhã.

Sheet Estabilidade
A1: Estabilidade do modelo final (k=6)
A3: Teste | B3: Resultado | C3: Leitura
A4: Concordância do nome do grupo entre 5 sementes/amostras (média) | B4: 0.982956 | C4: 98% dos clientes recebem o mesmo grupo ao trocar semente e amostra de treino.
A5: Concordância mínima | B5: 0.97433 | C5: Pior caso entre as 5 sementes.
A6: ARI médio entre rodadas | B6: 0.96085026 | C6: Muito estável a semente.
A7: ARI ao remover NPS | B7: 0.62503016 | C7: Os grupos mudam bastante sem NPS: dependem dele. Na vida real só há NPS para respondentes.
A8: ARI ao remover presente | B8: 0.72240538 | C8: Mudam moderadamente sem a variável presente.
A9: ARI k=5 vs k=6 / k=6 vs k=7 | C9: 0,69 e 0,76: ao mudar k, parte dos grupos se divide em vez de se reembaralhar.

Sheet Cancelamento por canal
A1: Taxa de cancelamento por canal de aquisição (24 meses, 1,92 mi assinaturas)
A2: % cancelados acumulado depende da idade da safra; churn mensal = cancelados / ciclos cobrados corrige a exposição.
A4: Aquisição | B4: Origem | C4: Canal | D4: Assinaturas | E4: Cancelados | F4: Ciclos cobrados | G4: % cancelados (acumulado) | H4: Churn mensal (cancel./ciclo)
A5: Mídia paga | B5: Internet (cartão) | C5: Afiliados/CPA | D5: 69342 | E5: 54748 | F5: 248173 | G5: =E5/D5 -> 0.78953592 | H5: =E5/F5 -> 0.22060418
A6: Mídia paga | B6: Internet (cartão) | C6: Programática/Display | D6: 60673 | E6: 47515 | F6: 224344 | G6: =E6/D6 -> 0.78313253 | H6: =E6/F6 -> 0.21179528
A7: Mídia paga | B7: Internet (cartão) | C7: Meta Ads | D7: 148369 | E7: 114336 | F7: 582114 | G7: =E7/D7 -> 0.7706192 | H7: =E7/F7 -> 0.19641514
A8: Mídia paga | B8: Telecom Claro (fatura) | C8: Afiliados/CPA | D8: 45454 | E8: 33452 | F8: 196483 | G8: =E8/D8 -> 0.73595283 | H8: =E8/F8 -> 0.17025392
A9: Mídia paga | B9: Telecom Claro (fatura) | C9: Programática/Display | D9: 39921 | E9: 29206 | F9: 177518 | G9: =E9/D9 -> 0.7315949 | H9: =E9/F9 -> 0.16452416
A10: Mídia paga | B10: Internet (cartão) | C10: Google Ads | D10: 156994 | E10: 114508 | F10: 697714 | G10: =E10/D10 -> 0.72937819 | H10: =E10/F10 -> 0.16411882
A11: Mídia paga | B11: Telecom Claro (fatura) | C11: Meta Ads | D11: 96679 | E11: 68531 | F11: 454926 | G11: =E11/D11 -> 0.70885094 | H11: =E11/F11 -> 0.15064208
A12: Mídia paga | B12: Telecom Claro (fatura) | C12: Google Ads | D12: 102568 | E12: 68660 | F12: 539647 | G12: =E12/D12 -> 0.66940956 | H12: =E12/F12 -> 0.12723132
A13: Orgânico | B13: Internet (cartão) | C13: App stores (orgânico) | D13: 59796 | E13: 37204 | F13: 351364 | G13: =E13/D13 -> 0.62218209 | H13: =E13/F13 -> 0.1058845
A14: Orgânico | B14: Internet (cartão) | C14: Site/SEO direto | D14: 94628 | E14: 57565 | F14: 571424 | G14: =E14/D14 -> 0.60832946 | H14: =E14/F14 -> 0.10073956
A15: Orgânico | B15: Internet (cartão) | C15: CRM e-mail (base interessada) | D15: 61211 | E15: 37225 | F15: 369797 | G15: =E15/D15 -> 0.60814233 | H15: =E15/F15 -> 0.10066334
A16: Orgânico | B16: Telecom Claro (fatura) | C16: Televendas/Lojas Claro | D16: 179623 | E16: 103554 | F16: 1153394 | G16: =E16/D16 -> 0.57650746 | H16: =E16/F16 -> 0.089781983
... A21: Orgânico | B21: Telecom Claro (fatura) | C21: Indicação (cliente Claro) | D21: 48221 | E21: 22377 | F21: 375079 | G21: =E21/D21 -> 0.46405093 | H21: =E21/F21 -> 0.059659432
A23: Total | D23: =SUM(D5:D22) -> 1920000 | E23: =SUM(E5:E22) -> 1185679 | F23: =SUM(F5:F22) -> 11285015 | G23: =E23/D23 -> 0.61754115 | H23: =E23/F23 -> 0.10506667
A25: Resumo por origem x aquisição
A26: Origem | B26: Aquisição | C26: Assinaturas | D26: Cancelados | E26: Ciclos | F26: % cancelados | G26: Churn mensal
A27: Internet (cartão) | B27: Mídia paga | C27: 435378 | D27: 331107 | E27: 1752345 | F27: =D27/C27 -> 0.76050466 | G27: =D27/E27 -> 0.18895081
A28: Internet (cartão) | B28: Orgânico | C28: 234435 | D28: 141838 | E28: 1425894 | F28: =D28/C28 -> 0.60502058 | G28: =D28/E28 -> 0.099473032
A29: Telecom Claro (fatura) | B29: Mídia paga | C29: 284622 | D29: 199849 | E29: 1368574 | F29: =D29/C29 -> 0.70215584 | G29: =D29/E29 -> 0.14602718
A30: Telecom Claro (fatura) | B30: Orgânico | C30: 965565 | D30: 512885 | E30: 6738202 | F30: =D30/C30 -> 0.53117605 | G30: =D30/E30 -> 0.076116002

Sheet Top 20% da receita
A1: Concentração de receita
A3: Base | B3: Top 1% | C3: Top 10% | D3: Top 20% | E3: Top 50%
A4: Todas as 1,92 mi assinaturas (receita acumulada em 24m) | B4: 0.055462915 | C4: 0.38008502 | D4: 0.59284404 | E4: 0.88909651
A5: Base ativa em 26/07/2026 (valor pago até a data) | B5: 0.034908972 | C5: 0.28629133 | D5: 0.48100485 | E5: 0.83097266
A7: Leitura: os 20% melhores clientes geram 59% da receita acumulada (todas as assinaturas, incluindo canceladas) e 48% na base ativa; é concentração moderada, menor que Pareto 80/20, porque o preço é por plano e a receita varia sobretudo por tempo de casa e aluguéis.

Sheet Base atual (usar amanhã)
A1: Aplicação dos mesmos centróides à base ativa em 24/10/2026 (734 mil clientes)
A2: Arquivo com o grupo por cliente: clientes_ativos_segmentados.csv.gz
A4: Grupo | B4: Clientes | C4: Valor pago acumulado (R$) | D4: % clientes | E4: % valor
A5: Cinéfilos de cupom | B5: 187854 | C5: 2.0311665e+08 | D5: =B5/SUM($B$5:$B$10) -> 0.25582 | E5: =C5/SUM($C$5:$C$10) -> 0.39625216
A6: Esfriando (alto valor) | B6: 101466 | C6: 71287089 | D6: =B6/SUM($B$5:$B$10) -> 0.13817663 | E6: =C6/SUM($C$5:$C$10) -> 0.13907114
A7: Fiéis a preço cheio | B7: 173416 | C7: 1.8053956e+08 | D7: =B7/SUM($B$5:$B$10) -> 0.2361583 | E7: =C7/SUM($C$5:$C$10) -> 0.35220742
A8: Novatos em experimentação | B8: 148740 | C8: 25053957 | D8: =B8/SUM($B$5:$B$10) -> 0.20255447 | E8: =C8/SUM($C$5:$C$10) -> 0.048876765
A9: Presenteados | B9: 38558 | C9: 24093848 | D9: =B9/SUM($B$5:$B$10) -> 0.052508372 | E9: =C9/SUM($C$5:$C$10) -> 0.047003727
A10: Quase perdidos | B10: 84287 | C10: 8503322.8 | D10: =B10/SUM($B$5:$B$10) -> 0.11478223 | E10: =C10/SUM($C$5:$C$10) -> 0.016588793

Sheet Decisões a NÃO tomar
A1: Decisões que NÃO devem ser tomadas só com esta segmentação
A3: Decisão | B3: Por quê
A4: Dar/retirar desconto por grupo sem teste A/B com controle | B4: O grupo descreve correlação. Cinéfilos de cupom e Fiéis a preço cheio têm churn parecido; desconto pode só canibalizar margem.
A5: Reajustar preço ou mudar planos | B5: O agrupamento não mede elasticidade de preço.
A6: Cortar ou ampliar canais/mídia paga | B6: Lift dos canais por grupo é baixo (1,1x a 1,7x). Decisão de mídia deve usar LTV/CAC e incrementalidade.
A7: Abandonar o atendimento dos "Quase perdidos" | B7: Valor baixo hoje não implica valor baixo amanhã; teste ações baratas antes de descartar.
A8: Confiar no NPS como se existisse para toda a base | B8: Aqui o NPS é sintético para todos; na vida real só há respondentes (tipicamente 10% a 25%) e sem NPS os grupos mudam (ARI 0,63).
A9: Assumir que presente existe como produto/fluxo | B9: "Presente" é hipótese de negócio sintética; confirmar se o produto existe e como é registrado.
A10: Interpretar a taxa de cancelamento por grupo como causal | B10: Backtest com features medidas até o cancelamento (vazamento leve); a separação real pode ser menor.
A11: Usar para cobrança, crédito ou negar serviço | B11: Uso de dados para marketing exige base legal/consentimento (LGPD); não é critério de crédito.
A12: Congelar os grupos | B12: Re-treinar a cada trimestre; novos preços, catálogo e sazonalidade (dez/jan) deslocam os centróides.
A13: Tirar conclusões de dados sintéticos | B13: Os números mostram o método e a ordem de grandeza; recalibrar com a base real antes de investir.

Sheet Dados por plano
A1: Dados de apoio: grupo x plano (alimenta o filtro)
A2: Base ativa em 26/07/2026 (clusters) e base ativa em 24/10/2026 (aplicação). Plano NÃO entra no k-means; é só filtro.
A4: Plano | B4: Grupo | C4: Clientes (26/07) | D4: Valor pago acumulado (R$) | E4: Cancelamentos em 90 dias | F4: Cupons (soma) | G4: Clientes ativos hoje (24/10) | H4: Valor pago hoje (R$)
A5: Premiere Futebol | B5: Cinéfilos de cupom | C5: 50122 | D5: 40853573 | E5: 5267 | F5: 66659.822 | G5: 58087 | H5: 51652394
A6: Premiere Futebol | B6: Fiéis a preço cheio | C6: 39985 | D6: 31497991 | E6: 3562 | F6: 0 | G6: 49472 | H6: 42023637
A7: Premiere Futebol | B7: Esfriando (alto valor) | C7: 37362 | D7: 22714988 | E7: 8938 | F7: 10075.954 | G7: 36182 | H7: 23355018
A8: Premiere Futebol | B8: Novatos em experimentação | C8: 39871 | D8: 6581615.9 | E8: 6826 | F8: 12961.411 | G8: 45341 | H8: 6958127
A9: Premiere Futebol | B9: Presenteados | C9: 10527 | D9: 5087837.2 | E9: 2770 | F9: 5050.3186 | G9: 11649 | H9: 6042428.5
A10: Premiere Futebol | B10: Quase perdidos | C10: 28413 | D10: 2881089.6 | E10: 13102 | F10: 13465.735 | G10: 28580 | H10: 2778350.5
A11: Telecine | B11: Cinéfilos de cupom | C11: 33305 | D11: 19062374 | E11: 4343 | F11: 46695.202 | G11: 38397 | H11: 23817295
A12: Telecine | B12: Fiéis a preço cheio | C12: 24808 | D12: 13670896 | E12: 2634 | F12: 0 | G12: 30885 | H12: 18271110
A13: Telecine | B13: Esfriando (alto valor) | C13: 28255 | D13: 12234549 | E13: 7604 | F13: 7540.7202 | G13: 26848 | H13: 12180117
A14: Telecine | B14: Novatos em experimentação | C14: 34738 | D14: 4510243.7 | E14: 6581 | F14: 9986.2937 | G14: 38387 | H14: 4690571.5
A15: Telecine | B15: Presenteados | C15: 8435 | D15: 2589332.8 | E15: 2801 | F15: 3773.0545 | G15: 8925 | H15: 2918517.4
A16: Telecine | B16: Quase perdidos | C16: 29051 | D16: 2271171.1 | E16: 14612 | F16: 12139.762 | G16: 27405 | H16: 1981414.6
... A22: Plano Família Claro tv+ | B22: Quase perdidos | C22: 29302 | D22: 4093251.8 | E22: 16376 | F22: 13161.026 | G22: 28302 | H22: 3743557.8
